<?xml version="1.0" encoding="utf-8"?>
<robot name="dvrk_psm_tool_blande" xmlns:xacro="http://www.ros.org/wiki/xacro">

  <!-- This file contains different tool urdf -->

  <!-- sca  -->

    <link name="base_link">
      <visual>
        <origin rpy="0 0 0" xyz="0 0 0"/>
        <geometry>
          <box size="0.001 0.001 0.001" />
        </geometry>
      </visual>
    </link>


    <!-- joint 5: Outer wrist pitch joint -->
    <joint name="outer_wrist_pitch" type="revolute">
       <parent link="base_link"/>
      <child link="tool_wrist_sca_link"/>
      <axis xyz="0 0 1"/>
      <origin rpy="-1.5708 -1.5708 0" xyz="0 0 0"/>
      <limit lower="-1.5707" upper="1.5707" velocity=".4" effort="1000"/>
    </joint>

    <!-- link 5: tool_wrist_sca_link -->
    <link name="tool_wrist_sca_link">
      <visual>
        <!-- <origin rpy="0 3.1416 0" xyz="0 0 0"/> -->
        <origin rpy="1.5708 3.1416 0" xyz="0.0051 0.0032 0"/>
        <geometry>
          <mesh filename="package://dvrk_model/meshes/psm/tool_wrist_sca_link.stl"/>
        </geometry>
      </visual>
      <collision>
        <!-- <origin rpy="0 3.1416 0" xyz="0 0 0"/> -->
        <origin rpy="1.5708 3.1416 0" xyz="0.0051 0.0032 0"/>
        <geometry>
          <mesh filename="package://dvrk_model/meshes/psm/tool_wrist_sca_link.stl"/>
        </geometry>
      </collision>
    </link>

    <!-- joint 6: Outer wrist yaw joint -->
    <joint name="outer_wrist_yaw" type="revolute">
      <parent link="tool_wrist_sca_link"/>
      <child link="tool_wrist_sca_shaft_link"/>
      <axis xyz="0 0 1"/>
      <origin rpy="-1.5708 -1.5708 0" xyz="0.0091 0 0"/>
      <!-- +/- 80 deg -->
      <limit lower="-1.3963" upper="1.3963" velocity=".4" effort="1000"/>
    </joint>

    <!-- link 6: tool_wrist_sca_shaft_link -->
    <link name="tool_wrist_sca_shaft_link">
      <visual>
        <origin rpy="0 0 0" xyz="0 -0.0002 -0.0025"/>
        <geometry>
          <mesh filename="package://dvrk_model/meshes/psm/tool_wrist_sca_shaft_link.stl"/>
        </geometry>
      </visual>
      <collision>
        <origin rpy="0 0 0" xyz="0 -0.0002 -0.0025"/>
        <geometry>
          <mesh filename="package://dvrk_model/meshes/psm/tool_wrist_sca_shaft_link.stl"/>
        </geometry>
      </collision>
    </link>

    <!-- joint 7-0: Outer open angle 1  -->
    <joint name="jaw" type="revolute">
      <parent link="tool_wrist_sca_shaft_link"/>
      <child link="tool_wrist_sca_ee_link_0"/>
      <axis xyz="0 1 0"/>
      <origin rpy="0 0 0" xyz="0 0 0"/>
      <limit lower="0" upper="1.5707" velocity=".4" effort="1000"/>
    </joint>

    <!-- link 7-0: Outer open angle virtual -->
    <link name="tool_wrist_sca_ee_link_0">
      <visual>
        <origin rpy="0 0 0" xyz="0 0 0"/>
        <geometry>
          <box size="0.45 0.05 0.001" />
        </geometry>
      </visual>
      <collision>
        <origin rpy="0 0 0" xyz="0 0 0"/>
        <geometry>
          <box size="0.45 0.05 0.001" />
        </geometry>
      </collision>
    </link>

 
    <!-- tool tip -->
    <joint name="tool_tip" type="fixed">
      <parent link="tool_wrist_sca_shaft_link"/>
      <child link="tool_tip_link"/>
      <origin rpy="0 1.5708 1.5708" xyz="0 0.45 0"/>
    </joint>
    <link name="tool_tip_link"/>

</robot>
